<?xml version="1.0"?>
<robot name="robot" xmlns:xacro="http://www.ros.org/wiki/xacro">
    <xacro:include filename="$(find robot_description)/urdf/robot.gazebo"/>
    <xacro:property name="chassis_mass" value="10" />
    <link name="base_link">
    </link>
    <link name="link_chassis">
        <inertial>
            <mass value="${chassis_mass}"/>
            <origin xyz="0 0 0.3" rpy="0 0 0"/>
            <inertia ixx="1.5417" ixy="0" ixz="0" iyy="3.467" iyz="0" izz="4.742"/>
        </inertial>
        <collision>
            <geometry>
                <box size="2 1.3 0.4"/>
            </geometry>
        </collision>
        <visual>
            <geometry>
                <mesh filename="package://robot_description/meshes/chassis.stl"/>
            </geometry>
            <material name="purple"/>
        </visual>
    </link>
    <joint name="base_chassis_joint" type="fixed">
        <origin xyz="0 0 0.42" rpy="0 0 0"/>
        <parent link="base_link"/>
        <child link="link_chassis"/> 
    </joint>

    <link name="link_left_wheel">
        <inertial>
            <mass value="1" />
            <origin xyz="0 0 0" rpy="0 0 0" />
            <inertia ixx="0.002526666666667" ixy="0" ixz="0" iyy="0.002526666666667" iyz="0" izz="0.005"/>
        </inertial>

        <!-- Tires -->
        <collision>
            <origin rpy="${pi/2} 0 0" xyz="0 0.18 0" />
            <geometry>
                <cylinder length="0.12" radius="0.4"/>
            </geometry>
        </collision>
        <visual>
            <origin rpy="${pi/2} 0 0" xyz="0 0.18 0" />
            <geometry>
                <mesh filename="package://robot_description/meshes/wheel.stl"/>
            </geometry>
            <material name="Black">
                <color rgba="0.1 0.1 0.1 1" />
            </material>
        </visual>

        <!-- Axle -->
        <collision>
            <origin rpy="${pi/2} 0 0" xyz="0 0.06 0" />
            <geometry>
                <cylinder length="0.12" radius="0.08"/>
            </geometry>
        </collision>
        <visual>
            <origin rpy="${pi/2} 0 0" xyz="0 0.06 0" />
            <geometry>
                <cylinder length="0.12" radius="0.08"/>
            </geometry>
            <material name="Grey">
                <color rgba="0.6 0.6 0.6 1" />
            </material>
        </visual>

        <!-- Hubcap -->
        <visual>
            <origin rpy="${pi/2} 0 0" xyz="0 0.25 0" />
            <geometry>
                <box size="0.02 0.5 0.02" />
            </geometry>
            <material name="Grey">
                <color rgba="0.6 0.6 0.6 1" />
            </material>
        </visual>
    </link>

    <joint name="joint_chassis_left_wheel" type="continuous">
        <origin xyz="-0.5 0.65 0" rpy="0 0 0"/>
        <parent link="link_chassis"/>
        <child link="link_left_wheel"/>
        <limit effort="10000" velocity="1000"/>
        <joint_properties damping="1.0" friction="1.0"/>
        <axis xyz="0 1 0" rpy="0 0 0"/>
    </joint>
    <link name="link_right_wheel">
        <inertial>
            <mass value="1" />
            <origin xyz="0 0 0" rpy="0 0 0" />
            <inertia ixx="0.002526666666667" ixy="0" ixz="0" iyy="0.002526666666667" iyz="0" izz="0.005"/>
        </inertial>

        <!-- Tires -->
        <collision>
            <origin rpy="${pi/2} 0 0" xyz="0 -0.18 0" />
            <geometry>
                <cylinder length="0.12" radius="0.4"/>
            </geometry>
        </collision>
        <visual>
            <origin rpy="${pi/2} 0 0" xyz="0 -0.18 0" />
            <geometry>
                <mesh filename="package://robot_description/meshes/wheel.stl"/>
            </geometry>
            <material name="Black">
                <color rgba="0.1 0.1 0.1 1" />
            </material>
        </visual>

        <!-- Axle -->
        <collision>
            <origin rpy="${pi/2} 0 0" xyz="0 -0.06 0" />
            <geometry>
                <cylinder length="0.12" radius="0.08"/>
            </geometry>
        </collision>
        <visual>
            <origin rpy="${pi/2} 0 0" xyz="0 -0.06 0" />
            <geometry>
                <cylinder length="0.12" radius="0.08"/>
            </geometry>
            <material name="Grey">
                <color rgba="0.6 0.6 0.6 1" />
            </material>
        </visual>

        <!-- Hubcap -->
        <visual>
            <origin rpy="${pi/2} 0 0" xyz="0 -0.25 0" />
            <geometry>
                <box size="0.02 0.5 0.02" />
            </geometry>
            <material name="Grey">
                <color rgba="0.6 0.6 0.6 1" />
            </material>
        </visual>
    </link>

    <joint name="joint_chassis_right_wheel" type="continuous">
        <parent link="link_chassis"/>
        <child link="link_right_wheel"/>
        <origin xyz="-0.5 -0.65 0" rpy="0 0 0"/>
        <effort limit="10000" velocity="1000"/>
        <joint_properties damping="1.0" friction="1.0"/>
        <axis xyz="0 1 0" rpy="0 0 0"/>
    </joint>
    <link name="link_caster_wheel">
        <inertial>
            <mass value="1" />
            <origin xyz="0 0 0" rpy="0 0 0" />
            <inertia ixx="0.002526666666667" ixy="0" ixz="0" iyy="0.002526666666667" iyz="0" izz="0.005"/>
        </inertial>
        <collision>
            <origin rpy="0 0 0" xyz="0 0 -0.03" />
            <geometry>
                <sphere radius="0.2" />
            </geometry>
        </collision>
        <visual>
            <origin rpy="0 0 0" xyz="0 0 -0.03" />
            <geometry>
                <sphere radius="0.2" />
            </geometry>
            <material name="DarkBlue">
                <color rgba="0.2 0.2 0.4 1" />
            </material>
        </visual>
        <collision>
            <origin rpy="0 0 0" xyz="0 0 -0.15" />
            <geometry>
                <sphere radius="0.10" />
            </geometry>
        </collision>
        <visual>
            <origin rpy="0 0 0" xyz="0 0 -0.15" />
            <geometry>
                <sphere radius="0.10" />
            </geometry>
            <material name="Grey">
                <color rgba="0.6 0.6 0.6 1" />
            </material>
        </visual>
    </link>
    <joint name="caster_wheel_chassis_joint" type="fixed">
        <origin xyz="0.8 0 -0.15" rpy="0 0 0"/>
        <parent link="link_chassis"/>
        <child link="link_caster_wheel"/>
        <joint_properties friction="0.0"/>
    </joint>
<!-- Differential Drive Plugin -->

<!--laser_scan-->
    <joint name="joint_laser_scan" type="fixed">
        <parent link="link_chassis"/>
        <child link="link_laser_scan"/>
        <origin rpy="0 0 0" xyz="0.8 0 0.3"/>
        <joint_properties damping="1.0" friction="1.0"/>
    </joint> 
    <link name="link_laser_scan">
        <inertial>
            <origin xyz="0 0 0" rpy="0 0 0"/>
            <mass value="0.5"/>
            <inertia ixx="0.000252666666667" ixy="0" ixz="0" iyy="0.000252666666667" iyz="0" izz="0.0005"/>
        </inertial>
        <visual>
            <origin xyz="0 0 0" rpy="0 0 0"/>
            <geometry>
                <cylinder radius="0.15" length="0.20"/>
            </geometry>
            <material name="Red">
                <color rgba="0.8 0 0 1"/>
            </material>
        </visual>
        <collision>
            <origin xyz="0 0 0" rpy="0 0 0"/>
            <geometry>
                <cylinder radius="0.15" length="0.20"/>
            </geometry>
        </collision>
    </link>
</robot>